Workbook
Name climate: #REF!
Name climate: #REF!
Name climate: #REF!
Name cooling: #REF!
Name cooling: #REF!
Name cooling: #REF!
Name interfaces: #REF!
Name interfaces: #REF!
Name interfaces: #REF!
Name package: #REF!
Name package: #REF!
Name package: #REF!
Name profiles: #REF!
Name profiles: #REF!
Name profiles: #REF!
Name profiles: #REF!
Name profiles: #REF!

Sheet Cover
H3: Document ID | I3: =F18 -> ELM-803-FS-0001
H4: Author | I4: =F19 -> Safety Manager | J4: =Cover!$G$19 -> I. Kök
H5: Version | I5: =F20 -> B2
H6: Status | I6: =F21 -> approved after review
A7: FMEDA
A9: ID803 - Vega
D18: Document ID | F18: ELM-803-FS-0001
D19: Author | F19: Safety Manager | G19: I. Kök
D20: Version | F20: B2
D21: Status | F21: approved after review
F30: Name | G30: Role | H30: Signature | I30: Date
D31: Prepared by | F31: THLN | G31: Consult | I31: 45910
D32: Reviewed by | F32: Fazil Civan | G32: Analog Design | I32: 45991
D33: Checked by
D34: Approved by | F34: Ismail Kök | G34: Safety Manager | I34: 45911
D40: History
D41: Author | E41: Version | F41: Change | G41: Date
D42: THLN | E42: 0.1 | F42: initial setup | G42: 45855
D43: THLN | E43: 0.2 | F43: Description of blocks, SM-list, lambda die | G43: 45856
D44: THLN | E44: 0.3 | F44: excel-FMEDA 803 die FMEDA | G44: 45864
D45: THLN | E45: 0.4 | F45: excel-FMEDA 803 package FMEDA | G45: 45865
D46: THLN | E46: 0.5 | F46: DFA | G46: 45867
D47: THLN | E47: 0.6 | F47: Final | G47: 45869
D48: THLN | E48: 0.7 | F48: Update due to review | G48: 45888
D49: THLN | E49: 0.8 | F49: Update due to MOBIS findings | G49: 45902
D50: THLN | E50: 0.9 | F50: Update | G50: 45903
D51: THLN | E51: 0.1 | F51: Update | G51: 45904
D52: THLN | E52: 0.11 | F52: Update | G52: 45905
D53: Fazil Civan | E53: 0.12 | F53: Update | G53: 45909
... D55: Fazil Civan | E55: 0.14 | F55: Review & update | G55: 45910
D56: Ismail Kök | E56: A | F56: Update to approval | G56: 45911
D57: Fazil Civan | E57: A.1 | F57: Update on Die_PKG Base and Core Block FIT rate tabs | G57: 45919
D58: Fazil Civan | E58: A.2 | F58: Update on SM_List, FMEDA to PIN (Near Short) | G58: 45922
D59: Fazil Civan | E59: A.3 | F59: Update on number of transistors | G59: 45923
D60: Fazil Civan | E60: A.4 | F60: SM coverage updates | G60: 45928
D61: Fazil Civan | E61: A.5 | F61: SM coverage updates | G61: 45933
D62: Fazil Civan | E62: B | F62: All of the tabs undergone updates | G62: 45943
D63: Fazil Civan | E63: B1 | F63: Typos fixed, effects on the systems columns filled | G63: 45958
D64: Fazil Civan | E64: B2 | F64: Typos fixed, PKG FIT rate multiplier removed, digital number of elements changed with NAND2*4 instead of direct transistor numbers. | G64: 45991

Sheet Block Diagram
J2: Document ID | L2: =Cover!$F$18 -> ELM-803-FS-0001
J3: Author | L3: =Cover!$F$19 -> Safety Manager | M3: =Cover!$G$19 -> I. Kök
J4: Version | L4: =Cover!$F$20 -> B2
J5: Status | L5: =Cover!$F$21 -> approved after review
A7: =Cover!A7 -> FMEDA
A9: =Cover!A9 -> ID803 - Vega
B11: Block Diagram
B50: Floor Plan
B87: Layout
M94: Die area | O94: Total area[mm^]
O95: Die area | P95: Block area | Q95: Pad

Sheet Description of Block
G2: Document ID | H2: =Cover!$F$18 -> ELM-803-FS-0001
G3: Author | H3: =Cover!$F$19 -> Safety Manager | I3: =Cover!$G$19 -> I. Kök
G4: Version | H4: =Cover!$F$20 -> B2
G5: Status | H5: =Cover!$F$21 -> approved after review
A6: FMEDA
A8: =Cover!A9 -> ID803 - Vega
B10: The System ASIC consists of the following group of functions
B11: No. | C11: HSR Block | D11: Description
B12: 1 | C12: REF | D12: Produces reference for mutliple IC blocks and secondary reference for ADC measurement.
B13: 2 | C13: BIAS | D13: Provides reference currents for multiple IC blocks.
B14: 3 | C14: LDO | D14: Produces supply to IC logic.
B15: 4 | C15: OSC | D15: Produce 16MHz frequency for logic.
B16: 6 | C16: TEMP | D16: Generate voltage proportional to die temperature.
B17: 7 | C17: CSNS | D17: generates voltage 0.4x or 4.0x of V(CSP, GND)
B18: 8 | C18: ADC | D18: Convert analog signals to a digital signal coded on 8 bits.
B19: 9 | C19: CP | D19: Produce supply for switch banks.
B20: 10 | C20: LOGIC | D20: IC main control
B21: 11 | C21: INTERFACE | D21: UART / digital interface
B22: 12 | C22: TRIM | D22: NVM block with configuration data
... B26: 16 | C26: SW_BANK_4 | D26: switch bank

Sheet SM list
I2: Document ID | K2: =Cover!$F$18 -> ELM-803-FS-0001
I3: Author | K3: =Cover!$F$19 -> Safety Manager | L3: =Cover!$G$19 -> I. Kök
I4: Version | K4: =Cover!$F$20 -> B2
I5: Status | K5: =Cover!$F$21 -> approved after review
B6: =Cover!A7 -> FMEDA
A8: =Cover!A9 -> ID803 - Vega
B10: List of Safety Mechanism
C11: SM# | D11: Development specification request No. | E11: Addressed Part | F11: Safety Mechanism / Measure | G11: IC Detection Method or Required Failsafe Solution | H11: Software (external MCU) Proposed Detection Method or Required Failsafe Solution | I11: IC Mitigation Action (action after detection) | J11: Argument | K11: ISO 26262-5 Annex D | L11: Diagnostic Coverage | M11: Comments
B12: 1 | C12: SM01 | D12: SR#83 | E12: REF, LDO | F12: Comparator: VDD Under-voltage | G12: Vega monitors system supply VDD pin voltage. If the supply voltage falls below a predefined threshold, the device transitions to OFF state, and all switches are set to open. | H12: check status registers for fails | I12: Vega resets internal logic and sets all switches to open. MCU re-inits switches after undervoltage | K12: D.2.1.2, tight comparator | L12: 0.99
B13: 2 | C13: SM02 | D13: SR#81 | E13: REF, LDO | F13: Comparator: VDD Over-voltage | G13: If VDD voltage exceeds the max nominal voltage, the switch between CPN and VDD is opened and the fault bit, VDD_OV_FLT, is set to 1. | H13: check status registers for fails | I13: Vega sets the switch between CPN and VDD to open. MCU re-inits switches after undervoltage | K13: D.2.1.2, tight comparator | L13: 0.99
B14: 3 | C14: SM03 | D14: SR#92 | E14: SW_BANK, LOGIC | F14: Comparator: Resistive FET Detection | G14: Resistive FET, when it is supposed to be short. If the voltage across the switch when it is shorted is more than the predefined threshold, all the corresponding bits in the FLT_LEDON are set in the volatile memory. | H14: check status registers for fails | I14: MCU resets IC | K14: D.2.1.2, tight comparator | L14: 0.99
B15: 4 | C15: SM04 | D15: SR#16 | E15: SW_BANK, LOGIC | F15: Comparator: LED Open Detection | G15: Vega monitors open condition across each SW FET. If the voltage across each switch exceeds predefined threshold, the switch FET is closed and all the corresponding bits in the FLT_LEDON are set in the volatile memory. | H15: check status registers for fails | I15: MCU resets IC | K15: D.2.1.2, tight comparator | L15: 0.99
B16: 5 | C16: SM05 | D16: SR#20 | E16: SW_BANK, LOGIC | F16: Comparator: LED Short Detection | G16: Vega monitors short condition across each SW FET and reports if the voltage across each switch decreases below the predefined threshold during the time that switch is supposed to be open, a corresponding register bit is set in the volatile memory. LED short condition is reported to MCU via UART. | H16: check status registers for fails | I16: MCU resets IC | K16: D.2.1.2, tight comparator | L16: 0.99
B17: 6 | C17: SM06 | D17: SR#28, 29 | E17: SW_BANK, LOGIC | F17: Driver Health Check | G17: To check the health of the SW FET driver, the DRV_CHK bit in the OUTCTRL register can be set by MCU. Upon setting this bit, all the gate driver outputs are disconnected from the output switches and the gate biases are pulled low. If all the switches are correctly turned off and are at high-z, all the corresponding bits in the FAULT_OPEN_OR_DRV are set to "1". | H17: check status registers for fails | I17: MCU resets IC | K17: D2.3.2, self-test supported by hardware | L17: 0.9
B18: 8 | C18: SM08 | D18: SR#33 | E18: CS, ADC | F18: ADC: LED Current Monitoring | G18: If the CSEN bit is set in the SYSCFG register, the voltage across CS pin and GND is measured using an ADC. The measured results are stored in the CS register in the volatile memory. | H18: check status registers for fails | I18: MCU resets IC | K18: D.2.4.4, monitoring outputs derated due to ADC sampling | L18: 0.9
B19: 9 | C19: SM09 | D19: SR#123 | E19: LOGIC | F19: UART Communication Watchdog | G19: If CMWEN bit in SYSCFG register is set, a CRC error check is performed on each UART transaction received from the MCU. If a valid UART transaction for more than a pre-programmed time is not received, the device enters the FAIL-SAFE state, and an associated error bit is set in the status register. | H19: check status registers for fails | I19: MCU resets IC | K19: D2.5.6, D2.5.7, D2.5.8 | L19: 0.99
B20: 10 | C20: SM10 | D20: SR#109 | E20: LOGIC | F20: Internal UART Watchdog Check | G20: A health check of the UART watchdog is performed upon power up. | H20: check status registers for fails | I20: Vega enters DIA2 state mode. MCU resets IC | K20: D2.5.8 | L20: 0.9
B21: 11 | C21: SM11 | E21: OSC | F21: Internal Clock Watchdog Check | G21: When ID803 operates with the internal clock, a clock watchdog monitors the clock. If the internal clock fails, a sys_reset to the digital is issued and all switches are set to open position. In this case PWR bit is set. | H21: check status registers for fails | I21: Vega sets the corresponding switch open. MCU re-inits switches | K21: D2.7.3 | L21: 0.6
B22: 12 | C22: SM12 | E22: SW_BANK, LOGIC | F22: PWM Monitoring | G22: The diagnostic PWM counter checks the output of each channel PWM counter in a round robin to make sure the output of each PWM counter is as programmed. If a PWM error count occurs, PWM_ERR bit is set in the STATUS register and a bit for a corresponding PWM counter is set in the PWM_MISCOUNT registers. | H22: check status registers for fails | I22: MCU resets IC | K22: D2.7.2 | L22: 0.9
B23: 13 | C23: SM13 | D23: SR#74 | E23: SW_BANK, LOGIC | F23: Comparator: FS Pin State | G23: During FAIL-SAFE state, switches are set according to the FS-pin voltage, all switches shall be set to open if the voltage on the FS-pin is lower than VIL-TH, and shall be set to close if the voItage on the FS-pin is more than VIH-TH. The FS-pin can be connected to GND or the VDD. There is a FS_PIN bit in the STATUS1 register that shows the voltage level of the FS pin. | H23: check status registers for fails | I23: Vega turn off or turn on all switches according to FS pin status. MCU re-inits switches | K23: D.2.1.2, tight comparator | L23: 0.99
B24: 14 | C24: SM14 | D24: SR#53 | E24: CP | F24: Comparator: CP Voltage Monitoring | G24: The charge pump voltage is monitored. If the charge pump voltage is decreased below a threshold, all the switches are set to open position. The CHPMP_ERR bit is set in the STATUS2 register if a charge pump error occurs. | H24: check status registers for fails | I24: Vega sets the corresponding switch open. MCU re-inits switches | K24: D.2.1.2, tight comparator | L24: 0.99
B25: 15 | C25: SM15 | D25: SR#84,85 | E25: REF, LDO | F25: Comparator: Internal Supply Monitoring | G25: When 1.8V internal voltage goes out of a specified voltage range, it generates a POR that resets digital and sets the output switches to open. The LDO_UV_FLT bit is then set to default value of '1'. | H25: check status registers for fails | I25: Vega sets the corresponding switch open. MCU re-inits switches | K25: D.2.1.2, tight comparator | L25: 0.99
B26: 16 | C26: SM16 | E26: REF, ADC | F26: ADC: SBG ADC Reading | G26: IC features a secondary bandgap (typ. 1.2V) that's digitized using the primary bandgap's 2V reference. Results are stored in BGR register. | H26: check registers for fails | I26: MCU resets IC | K26: D.2.1.2, comparison but derated due to ADC sampling | L26: 0.9
B27: 17 | C27: SM17 | D27: SR#99 | E27: TEMP | F27: ADC: Thermal Limit | G27: The PTAT voltage generated by die temperature monitor module is measured by an ADC. The measured die temperature value is compared with 175C thermal limit in digital. The TLMT bit is set in STATUS2 register if thermal limit occurs. | H27: check status registers for fails | I27: When TSDEN<1:0> is set to 0x00, there is no action is taken for the switches when TLIMIT is reached. When it is set to 0x03, switches are set to open when TLIMIT is reached.n and MCU resets IC. | K27: D.2.1.2, comparison but derated due to ADC sampling | L27: 0.9
B28: 18 | C28: SM18 | E28: LOGIC | F28: ECC | G28: The ECC will correct 1 bit error and detect 2 bit error. | H28: check status registers for fails | I28: MCU resets IC | K28: D2.5.2 withSECDED and short exposition by NVM copy | L28: 0.99
B29: 20 | C29: SM20 | E29: LDO | F29: Comparator: LDO Overvoltage | G29: check against set limits | H29: check status registers for fails | I29: MCU wait for normal voltage | K29: D.2.1.2, tight comparator | L29: 0.99
B30: 21 | C30: SM21 | E30: LOGIC | F30: SYNC Monitor | G30: The bit is set when SYNC pulse high duration is within ±6.25% of PWM register configuration, and reset if it is out of range | H30: check status registers for fails | I30: MCU resets IC | K30: D2.6.1 | L30: 0.6
B31: 22 | C31: SM22 | E31: CP, SW_BANK | F31: Matrix SW POR | G31: If the floating supply in the switch module falls below a defined threshold, the switch is set to open. This mechanism is triggered if the internal supply to the regulator or the VDD supply, or the charge pump fails. ID803 sets the corresponding switch open and all the corresponding bits in the FLT_MATRIX_POR register are set to "1". | H31: check status registers for fails | I31: MCU resets IC | K31: D.2.1.2, D2.4.4 | L31: 0.99
B32: 23 | C32: SM23 | E32: TEMP | F32: ADC: Thermal Monitoring | G32: Die temperature measured and stored in DIETEMP register. | H32: check status registers for fails | I32: MCU resets IC | K32: D.2.1.2, D2.4.4 | L32: 0.9
B33: 24 | C33: SM24 | E33: ADC, SW_BANK | F33: ADC: LED Switch Voltage Detection | G33: LEDx voltage monitoring with ADC. Results written on VLEDON registers. A comparison with LEDONTH done digitally. | H33: check status registers for fails | I33: MCU resets IC | K33: D.2.1.2, comparison but derated due to ADC sampling | L33: 0.9

Sheet Die_PKG Base Failure rate
X2: Document ID | Z2: =Cover!$F$18 -> ELM-803-FS-0001
X3: Author | Z3: =Cover!$F$19 -> Safety Manager | AA3: =Cover!$G$19 -> I. Kök
X4: Version | Z4: =Cover!$F$20 -> B2
X5: Status | Z5: =Cover!$F$21 -> approved after review
A8: =Cover!A7 -> FMEDA
A10: =Cover!A9 -> ID803 - Vega
B12: Internal Use Only
R15: λ1 | S15: per transistor base failure rate of the integrated circuit family. See Table 16.
R16: λ2 | S16: failure rate related to the technology mastering of the integrated circuit. See Table 16.
R17: N | S17: number of transistors of the integrated circuit.
R18: α | S18: [(year of manufacturing) – 1998].
R19: π1 | S19: ith temperature factor related to the ith junction temperature of the integrated circuit mission profile.
R20: τi | S20: ith working time ratio of the integrated circuit for the ith junction temperature of the mission profile.
R21: τon | S21: total working time ratio of the integrated circuit. With:τon=Στi
R22: τoff | S22: time ratio for the integrated circuit being in storage (or dormant). With τon +τoff =1
R26: =C149 -> ■ Die FIT rate (①X②) | T26: =E149 -> 6.3327874 | U26: =F149 -> FIT
R27: =C200 -> ■ PKG FIT rate | T27: =E200 -> 73.243732 | U27: =F200 -> FIT
R28: =B202 -> ■ IC Total FIT rate | T28: =E202 -> 79.576519 | U28: =F202 -> FIT
C29: value in this column is used to calculate base failure rate. It should be described by engineer.
C30: value in this column is automatically calculated
C34: □ Number of Transistor
C36: - Analog part | E36: Cell unit (<6V) | F36: 29553
E37: Cell unit (>=6V) | F37: 308
C38: - Digital part | E38: Cell unit (NAND2*4) | F38: =62174*4 -> 248696
C41: □ λ1 & λ2 (Failure rate factor)
C42: - Analog part : <6V | E42: λ1 | F42: =2.7*0.0001 -> 0.00027 | H42: Refer to Table 16
E43: λ2 | F43: 20 | H43: Refer to Table 16
E44: N | F44: =F36 -> 29553
C46: - Analog part : >=6V | E46: λ1 | F46: =2.7*0.001 -> 0.0027 | H46: Refer to Table 16
E47: λ2 | F47: 20 | H47: Refer to Table 16
E48: N | F48: =F37 -> 308
C50: - Digital part | E50: λ1 | F50: =1*0.000001 -> 1e-06 | H50: Refer to Table 16
E51: λ2 | F51: 1.7 | H51: Refer to Table 16
E52: N | F52: =F38 -> 248696
C54: □ FAB Process stability
E56: year of manufacturing | F56: 2025
E57: α | F57: =F56-1998 -> 27
C61: ① Die base rate (w/o mission profile)
C62: - Analog part | E62: <6V | F62: =F42*F44*EXP(-0.35*F57) -> 0.00062788844
E63: >=6V | F63: =F46*F48*EXP(-0.35*F57) -> 6.5438242e-05
...

Sheet Core Block FIT rate
J2: Document ID | L2: =Cover!$F$18 -> ELM-803-FS-0001
J3: Author | L3: =Cover!$F$19 -> Safety Manager | M3: =Cover!$G$19 -> I. Kök
J4: Version | L4: =Cover!$F$20 -> B2
J5: Status | L5: =Cover!$F$21 -> approved after review
A7: =Cover!A7 -> FMEDA
A9: =Cover!A9 -> ID803 - Vega
B11: FIT rate calculation
C13: The basis of failure rate calculation is described here.
C15: FIT Rate | D15: Package | E15: ='Die_PKG Base Failure rate'!T27 -> 73.243732
D16: Die | E16: ='Die_PKG Base Failure rate'!T26 -> 6.3327874
C17: Total Die Area [mm^2] | E17: =12580000/(1000*1000) -> 12.58
C19: Name | E19: Area [mm^2] | F19: Block/Die | G19: λ [FIT]
C20: Block(total) | E20: =G48/(1000*1000) -> 12.296455 | F20: =E20/E$17 -> 0.97746068 | G20: =E16 -> 6.3327874 | H20: =Die FIT
F21: area / pad | G21: FIT
C22: Pad (protect diode short to VCC&GND, near pin short) | E22: 48 | F22: N/A | G22: =E15*0.1 -> 7.3243732 | H22: =0.1*Package FIT
C23: PIN (Pin open) | E23: N/A | F23: N/A | G23: =E15*0.9 -> 65.919358 | H23: =0.9*Package FIT
B25: Core Block FIT rate calculation
B30: Fit to block | E30: Width | F30: Height | G30: Area | H30: Number of blocks | I30: Adjust the Wiring Area | J30: Total Area | K30: Area Ratio | L30: FIT
B31: REF | E31: 800 | F31: 123.53731 | G31: 98829.85 | H31: 1 | I31: =1/$F$20 -> 1.0230591 | J31: =G31*H31*I31 -> 101108.77 | K31: =J31/$J$48 -> 0.0080372633 | L31: =K31*$G$20 -> 0.05089828
B32: BIAS | E32: 924 | F32: 176.5 | G32: 163086 | H32: 1 | I32: =1/$F$20 -> 1.0230591 | J32: =G32*H32*I32 -> 166846.61 | K32: =J32/$J$48 -> 0.013262846 | L32: =K32*$G$20 -> 0.083990787
B33: LDO | E33: 290.6 | F33: 251 | G33: 72940.6 | H33: 1 | I33: =1/$F$20 -> 1.0230591 | J33: =G33*H33*I33 -> 74622.541 | K33: =J33/$J$48 -> 0.0059318395 | L33: =K33*$G$20 -> 0.037565079
B34: OSC | E34: 465.2 | F34: 111.4 | G34: 51823.28 | H34: 1 | I34: =1/$F$20 -> 1.0230591 | J34: =G34*H34*I34 -> 53018.276 | K34: =J34/$J$48 -> 0.0042144893 | L34: =K34*$G$20 -> 0.026689465
B35: TEMP | E35: 172.3 | F35: 112.6 | G35: 19400.98 | H35: 1 | I35: =1/$F$20 -> 1.0230591 | J35: =G35*H35*I35 -> 19848.348 | K35: =J35/$J$48 -> 0.0015777701 | L35: =K35*$G$20 -> 0.0099916828
B36: CSNS | E36: 264.2 | F36: 267.3 | G36: 70620.66 | H36: 1 | I36: =1/$F$20 -> 1.0230591 | J36: =G36*H36*I36 -> 72249.105 | K36: =J36/$J$48 -> 0.0057431721 | L36: =K36*$G$20 -> 0.036370288
B37: ADC | E37: 252.5 | F37: 434.7 | G37: 109761.75 | H37: 1 | I37: =1/$F$20 -> 1.0230591 | J37: =G37*H37*I37 -> 112292.75 | K37: =J37/$J$48 -> 0.0089262919 | L37: =K37*$G$20 -> 0.056528309
B38: CP | E38: 864.8 | F38: 961.7 | G38: 831678.16 | H38: 1 | I38: =1/$F$20 -> 1.0230591 | J38: =G38*H38*I38 -> 850855.87 | K38: =J38/$J$48 -> 0.067635602 | L38: =K38*$G$20 -> 0.42832189
B39: LOGIC | E39: 1730 | F39: 742 | G39: 1283660 | H39: 1 | I39: =1/$F$20 -> 1.0230591 | J39: =G39*H39*I39 -> 1313260 | K39: =J39/$J$48 -> 0.10439269 | L39: =K39*$G$20 -> 0.66109669
B40: INTERFACE | E40: 263.8 | F40: 122.6 | G40: 32341.88 | H40: 1 | I40: =1/$F$20 -> 1.0230591 | J40: =G40*H40*I40 -> 33087.653 | K40: =J40/$J$48 -> 0.0026301791 | L40: =K40*$G$20 -> 0.016656365
B41: TRIM | E41: 376 | F41: 226.8 | G41: 85276.8 | H41: 1 | I41: =1/$F$20 -> 1.0230591 | J41: =G41*H41*I41 -> 87243.202 | K41: =J41/$J$48 -> 0.0069350717 | L41: =K41*$G$20 -> 0.043918335
B42: SW_BANK_1 | E42: 1311 | F42: 1765 | G42: 2313915 | H42: 1 | I42: =1/$F$20 -> 1.0230591 | J42: =G42*H42*I42 -> 2367271.7 | K42: =J42/$J$48 -> 0.1881774 | L42: =K42*$G$20 -> 1.1916875
... B44: SW_BANK_3 | E44: 1900 | F44: 1121.1367 | G44: 2130159.8 | H44: 1 | I44: =1/$F$20 -> 1.0230591 | J44: =G44*H44*I44 -> 2179279.2 | K44: =J44/$J$48 -> 0.17323364 | L44: =K44*$G$20 -> 1.0970518
B45: SW_BANK_4 | E45: 1900 | F45: 1122.8948 | G45: 2133500.2 | H45: 1 | I45: =1/$F$20 -> 1.0230591 | J45: =(G45*H45)*I45 -> 2182696.7 | K45: =J45/$J$48 -> 0.1735053 | L45: =K45*$G$20 -> 1.0987722
B46: SM Total | E46: - | F46: - | G46: 585545.5 | H46: 1 | I46: =1/$F$20 -> 1.0230591 | J46: =(G46*H46)*I46 -> 599047.62 | K46: =J46/$J$48 -> 0.047619048 | L46: =K46*$G$20 -> 0.30156131
B48: Total | G48: =SUM(G31:G46) -> 12296455 | H48: um2 | J48: =SUM(J31:J46) -> 12580000 | K48: =SUM(K31:K46) -> 1 | L48: =SUM(L31:L46) -> 6.3327874
G49: Total block areas | J49: Chip Area | K49: Check | L49: Die
B50: *The FIT below is reflected in FMEDA block FIT | F50: #1.0 | J50: =H50-I50 -> 0

Sheet FMEDA
C2: FMEDAフォーマット案1
AB3: Document ID | AD3: =Cover!$F$18 -> ELM-803-FS-0001
AD4: =Cover!$F$19 -> Safety Manager | AE4: =Cover!$G$19 -> I. Kök
AD5: =Cover!$F$20 -> B2
AD6: =Cover!$F$21 -> approved after review
A8: FMEDA
A10: =Cover!A9 -> ID803 - Vega
D11: Safety Goalが明確、ブロックベース分析
E12: This column should be described by engineer.
E13: This column is automatically calculated | Z13: MCU= | AA13: 0.6
J14: λ | K14: =SUM(E22:E162) -> 6.3327874
J15: λSPF+λRF | K15: =SUM(V22:V162) -> 0.10455336 | Z15: ABIST= | AA15: 0.6
J16: λLF | K16: =SUM(AB22:AB162) -> 0.74109836 | Z16: LBIST= | AA16: 0.91
I17: 고장Mode는 200개까지 대응. 200개이상의 경우에는 수식확인 할 것. | Z17: TSD= | AA17: 0.6
O18: Permanent Failures
G19: Part9 8.4.9 c) | H19: Part9 8.4.9 a) | I19: Part9 8.4.9 b) | J19: Part9 8.4.9 b) | O19: Single Point Failures | X19: Latent Failure
B20: 고장Mode번호 PSG (Pad Short to Power) | C20: 機能 | D20: Block | E20: Block 고장율(FIT) | F20: Failure mode separate fault rate | G20: 고장Mode(iso26262) | H20: 고장Mode | I20: IC단품으로써의 영향 | J20: ECU (시스템)에의 영향 | K20: IC단품영향에 대처와 판단 | O20: 비교 | P20: 안전에 걸리는지? | Q20: 항목고장율 (FIT) | R20: 안전고장의 비율 | S20: 안전기구 (IC) | T20: 안전기구 (System) | U20: 검출율 （SPF） | V20: 잔존고장의 고장율 (FIT) | X20: Latent Failure 는 안전에 걸리는지? | Y20: 안전기구 (IC) | Z20: 안전기구 (System) | AA20: 검출율 | AB20: Latent Failure 의 고장율 (FIT) | AD20: Comment
B21: Failure Mode Number | C21: Component Name | D21: Block Name | E21: Block Failure rate [FIT] | G21: Standard failure mode | H21: Failure Mode | I21: effects on the IC output | J21: effects on the system | K21: memo X - Violation of SG O - No violation | L21: System Comment | M21: system Request | O21: Failure distribution | P21: Single Point Failure mode can violate the safety goal in the absense of safety mecahnism | Q21: Failure rate [FIT] | R21: Percentage of Safe Faults | S21: Safety mechanism(s) (IC) allowing to prevent the violation of the safety goal | T21: Safety mechanism(s) (System) allowing to prevent the violation of the safety goal | U21: Failure mode coverage wrt. violation of safety goal | V21: Residual or Single Point Fault failure rate [FIT] | X21: Latent Failure mode can violate the safety goal in the absense of safety mecahnism | Y21: Safety mechanism(s) (IC) to prevent latent faults | Z21: Safety mechanism(s) (System) to prevent latent faults | AA21: Failure mode coverage wrt. Latent failures | AB21: Latent Multiple Point Fault failure rate [FIT]
B22: FM_TTL_1 | D22: REF | E22: ='Core Block FIT rate'!L31 -> 0.05089828 | F22: =E22/7 -> 0.0072711829 | G22: Output is stuck (i.e. high or low) | I22: • BIAS - Output reference voltage is stuck - Output reference current is stuck - Output bias current is stuck - Quiescent current exceeding the maximum value • REF - Quiescent current exceeding the maximum value • ADC - REF output is stuck • TEMP - Output is stuck • LDO - Output is stuck • OSC - Oscillation does not start | J22: Unintentional LED ON/OFF Fail-safe mode active No communication | K22: X | O22: 1 | P22: Y | Q22: =F22*O22 -> 0.0072711829 | R22: 0 | S22: SM01 SM15 SM16 SM17 | U22: 0.99 | V22: =IF(P22="N",0,Q22*(1-R22)*(1-U22)) -> 7.2711829e-05 | X22: Y | Y22: =S22 -> SM01 SM15 SM16 SM17 | AA22: 1 | AB22: =IF(X22="N",0,(Q22*(1-R22)-V22)*(1-AA22)) -> 0 | AD22: SM01 SM15 make the IC enter a safe-sate. Latent coverage: 100%.
B23: FM_TTL_2 | F23: =F22 -> 0.0072711829 | G23: Output is floating (i.e. open circuit) | I23: • BIAS - Output reference voltage is floating - Output reference current is higher than the expected range - Output reference current is lower than the expected range - Output bias current is higher than the expected range - Output bias current is lower than the expected range • ADC - REF output is floating (i.e. open circuit) • LDO - Out of spec • OSC - Out of spec | J23: Unintentional LED ON/OFF Fail-safe mode active No communication | K23: X | O23: 1 | P23: Y | Q23: =F23*O23 -> 0.0072711829 | R23: 0 | S23: SM01 SM15 SM16 SM17 | U23: 0.99 | V23: =IF(P23="N",0,Q23*(1-R23)*(1-U23)) -> 7.2711829e-05 | X23: Y | Y23: =S23 -> SM01 SM15 SM16 SM17 | AA23: 1 | AB23: =IF(X23="N",0,(Q23*(1-R23)-V23)*(1-AA23)) -> 0 | AD23: SM01 SM15 make the IC enter a safe-sate. Latent coverage: 100%.
B24: FM_TTL_3 | F24: =F23 -> 0.0072711829 | G24: Incorrect output voltage value (i.e. outside the expected range) | I24: • BIAS - Output reference voltage is higher than the expected range - Output reference current is higher than the expected range - Output bias current is higher than the expected range • TEMP - Incorrect gain on the output voltage (outside the expected range) - Incorrect offset on the output voltage (outside the expected range) • ADC - REF output higher/lower than expected • LDO - Out of spec • OSC - Out of spec | J24: Unintentional LED ON/OFF Fail-safe mode active No communication | K24: X | O24: 1 | P24: Y | Q24: =F24*O24 -> 0.0072711829 | R24: 0 | S24: SM01 SM11 SM15 SM16 | U24: 0.99 | V24: =IF(P24="N",0,Q24*(1-R24)*(1-U24)) -> 7.2711829e-05 | X24: Y | Y24: =S24 -> SM01 SM11 SM15 SM16 | AA24: 1 | AB24: =IF(X24="N",0,(Q24*(1-R24)-V24)*(1-AA24)) -> 0 | AD24: SM01 SM15 make the IC enter a safe-sate. Latent coverage: 100%.
B25: FM_TTL_4 | F25: =F24 -> 0.0072711829 | G25: Output voltage accuracy too low, including drift | I25: • BIAS - Output reference voltage is higher than the expected range - Output reference current is higher than the expected range - Output bias current is higher than the expected range • TEMP - Incorrect gain on the output voltage (outside the expected range) - Incorrect offset on the output voltage (outside the expected range) • ADC - REF output higher/lower than expected • LDO - Out of spec • OSC - Out of spec | J25: Unintentional LED ON/OFF Fail-safe mode active No communication | K25: X | O25: 1 | P25: Y | Q25: =F25*O25 -> 0.0072711829 | R25: 0 | S25: SM01 SM11 SM15 SM16 | U25: 0.99 | V25: =IF(P25="N",0,Q25*(1-R25)*(1-U25)) -> 7.2711829e-05 | X25: Y | Y25: =S25 -> SM01 SM11 SM15 SM16 | AA25: 1 | AB25: =IF(X25="N",0,(Q25*(1-R25)-V25)*(1-AA25)) -> 0 | AD25: SM01 SM15 make the IC enter a safe-sate. Latent coverage: 100%.
B26: FM_TTL_5 | F26: =F25 -> 0.0072711829 | G26: Output voltage affected by spikes | I26: No effect | J26: No effect | K26: O | O26: 1 | P26: N | Q26: =F26*O26 -> 0.0072711829 | R26: =IF(P26="N",100%,0%) -> 1 | X26: N
B27: FM_TTL_6 | F27: =F26 -> 0.0072711829 | G27: Output voltage oscillation within the expected range | I27: No effect | J27: No effect | K27: O | O27: 1 | P27: N | Q27: =F27*O27 -> 0.0072711829 | R27: =IF(P27="N",100%,0%) -> 1 | X27: N
B28: FM_TTL_7 | F28: =F27 -> 0.0072711829 | G28: Incorrect start-up time (i.e. outside the expected range) | I28: No effect | J28: No effect | K28: O | O28: 1 | P28: N | Q28: =F28*O28 -> 0.0072711829 | R28: =IF(P28="N",100%,0%) -> 1 | X28: N
B29: FM_TTL_8 | D29: BIAS | E29: ='Core Block FIT rate'!L32 -> 0.083990787 | F29: =E29/10 -> 0.0083990787 | G29: One or more outputs are stuck (i.e. high or low) | I29: • ADC - ADC measurement is incorrect. • TEMP - Incorrect temperature measurement. • LDO - Out of spec. • OSC - Frequency out of spec. • SW_BANKx - Out of spec. • CP - Out of spec. • CNSN - Incorrect reading. | J29: Unintentional LED ON/OFF Fail-safe mode active No communication | K29: X | O29: 1 | P29: Y | Q29: =F29*O29 -> 0.0083990787 | R29: =IF(P29="N",100%,0%) -> 0 | S29: SM11 SM15 SM16 | U29: 0.99 | V29: =IF(P29="N",0,Q29*(1-R29)*(1-U29)) -> 8.3990787e-05 | X29: Y | Y29: =S29 -> SM11 SM15 SM16 | AA29: 1 | AB29: =IF(X29="N",0,(Q29*(1-R29)-V29)*(1-AA29)) -> 0 | AD29: SM15 make the IC enter a safe-sate. Latent coverage: 100%.
B30: FM_TTL_9 | F30: =F29 -> 0.0083990787 | G30: One or more outputs are floating (i.e. open circuit) | I30: • ADC - ADC measurement is incorrect. • TEMP - Incorrect temperature measurement. • LDO - Out of spec. • OSC - Frequency out of spec. • SW_BANKx - Out of spec. • CP - Out of spec. • CNSN - Incorrect reading. | J30: Unintentional LED ON/OFF Fail-safe mode active No communication | K30: X | O30: 1 | P30: Y | Q30: 0.0042040524 | R30: 0 | S30: SM11 SM15 SM16 | U30: 0.99 | V30: 4.2040524e-05 | X30: Y | Y30: =S30 -> SM11 SM15 SM16 | AA30: 1 | AB30: 0 | AD30: SM15 make the IC enter a safe-sate. Latent coverage: 100%.
B31: FM_TTL_10 | F31: =F30 -> 0.0083990787 | G31: Incorrect reference current (i.e. outside the expected range) | I31: • ADC - ADC measurement is incorrect. • TEMP - Incorrect temperature measurement. • LDO - Out of spec. • OSC - Frequency out of spec. • SW_BANKx - Out of spec. • CP - Out of spec. • CNSN - Incorrect reading. | J31: Unintentional LED ON/OFF Fail-safe mode active No communication | K31: X | O31: 1 | P31: Y | Q31: 0.0042040524 | R31: 0 | S31: SM11 SM15 SM16 | U31: 0.99 | V31: 4.2040524e-05 | X31: Y | Y31: =S31 -> SM11 SM15 SM16 | AA31: 1 | AB31: 0 | AD31: SM15 make the IC enter a safe-sate. Latent coverage: 100%.
B32: FM_TTL_11 | F32: =F31 -> 0.0083990787 | G32: Reference current accuracy too low , including drift | I32: • ADC - ADC measurement is incorrect. • TEMP - Incorrect temperature measurement. • LDO - Out of spec. • OSC - Frequency out of spec. • SW_BANKx - Out of spec. • CP - Out of spec. • CNSN - Incorrect reading. | J32: Unintentional LED ON/OFF Fail-safe mode active No communication | K32: X | O32: 1 | P32: Y | Q32: 0.0042040524 | R32: 0 | S32: SM11 SM15 SM16 | U32: 0.99 | V32: 4.2040524e-05 | X32: Y | Y32: =S32 -> SM11 SM15 SM16 | AA32: 1 | AB32: 0 | AD32: SM15 make the IC enter a safe-sate. Latent coverage: 100%.
B33: FM_TTL_12 | F33: =F32 -> 0.0083990787 | G33: Reference current affected by spikes | I33: No effect | J33: No effect | K33: O | O33: 1 | P33: N | Q33: =F33*O33 -> 0.0083990787 | R33: =IF(P33="N",100%,0%) -> 1 | X33: N
B34: FM_TTL_13 | F34: =F33 -> 0.0083990787 | G34: Reference current oscillation within the expected range | I34: No effect | J34: No effect | K34: O | O34: 1 | P34: N | Q34: =F34*O34 -> 0.0083990787 | R34: =IF(P34="N",100%,0%) -> 1 | X34: N
B35: FM_TTL_14 | F35: =F34 -> 0.0083990787 | G35: One or more branch currents outside the expected range while reference current is correct | I35: • ADC - ADC measurement is incorrect. • TEMP - Incorrect temperature measurement. • LDO - Out of spec. • OSC - Frequency out of spec. • SW_BANKx - Out of spec. • CP - Out of spec. • CNSN - Incorrect reading. | J35: Unintentional LED ON/OFF Fail-safe mode active No communication | K35: X | O35: 1 | P35: Y | Q35: 0.0042040524 | R35: 0 | S35: SM11 SM15 SM16 | U35: 0.99 | V35: 4.2040524e-05 | X35: Y | Y35: =S35 -> SM11 SM15 SM16 | AA35: 1 | AB35: 0 | AD35: SM15 make the IC enter a safe-sate. Latent coverage: 100%.
B36: FM_TTL_15 | F36: =F35 -> 0.0083990787 | G36: One or more branch currents accuracy too low , including drift | I36: • ADC - ADC measurement is incorrect. • TEMP - Incorrect temperature measurement. • LDO - Out of spec. • OSC - Frequency out of spec. • SW_BANKx - Out of spec. • CP - Out of spec. • CNSN - Incorrect reading. | J36: Unintentional LED ON/OFF Fail-safe mode active No communication | K36: X | O36: 1 | P36: Y | Q36: 0.0042040524 | R36: 0 | S36: SM11 SM15 SM16 | U36: 0.99 | V36: 4.2040524e-05 | X36: Y | Y36: =S36 -> SM11 SM15 SM16 | AA36: 1 | AB36: 0 | AD36: SM15 make the IC enter a safe-sate. Latent coverage: 100%.
B37: FM_TTL_16 | F37: =F36 -> 0.0083990787 | G37: One or more branch currents affected by spikes | I37: No effect | J37: No effect | K37: O | O37: 1 | P37: N | Q37: =F37*O37 -> 0.0083990787 | R37: =IF(P37="N",100%,0%) -> 1 | X37: N
B38: FM_TTL_17 | F38: =F37 -> 0.0083990787 | G38: One or more branch currents oscillation within the expected range | I38: No effect | J38: No effect | K38: O | O38: 1 | P38: N | Q38: =F38*O38 -> 0.0083990787 | R38: =IF(P38="N",100%,0%) -> 1 | X38: N
B39: FM_TTL_18 | D39: LDO | E39: ='Core Block FIT rate'!L33 -> 0.037565079 | F39: =E39/8 -> 0.0046956348 | G39: Output voltage higher than a high threshold of the prescribed range (i.e. over voltage — OV) | I39: • OSC - Out of spec. | J39: Fail-safe mode active No communication | K39: X | O39: 1 | P39: Y | Q39: =F39*O39 -> 0.0046956348 | R39: =IF(P39="N",100%,0%) -> 0 | S39: SM11 SM20 | U39: =IF(P39="N",0%,99%) -> 0.99 | V39: =IF(P39="N",0,Q39*(1-R39)*(1-U39)) -> 4.6956348e-05 | X39: Y | Y39: =S39 -> SM11 SM20 | AA39: 0.8 | AB39: =IF(X39="N",0,(Q39*(1-R39)-V39)*(1-AA39)) -> 0.0009297357
B40: FM_TTL_19 | F40: =F39 -> 0.0046956348 | G40: Output voltage lower than a low threshold of the prescribed range (i.e. under voltage — UV) | I40: • OSC - Out of spec. • Vega - Reset reaction. (POR) | J40: Fail-safe mode active No communication | K40: X | O40: 1 | P40: Y | Q40: =F40*O40 -> 0.0046956348 | R40: =IF(P40="N",100%,0%) -> 0 | S40: SM11 SM15 | U40: =IF(P40="N",0%,99%) -> 0.99 | V40: =IF(P40="N",0,Q40*(1-R40)*(1-U40)) -> 4.6956348e-05 | X40: Y | Y40: =S40 -> SM11 SM15 | AA40: 0.8 | AB40: =IF(X40="N",0,(Q40*(1-R40)-V40)*(1-AA40)) -> 0.0009297357
B41: FM_TTL_20 | F41: =F40 -> 0.0046956348 | G41: Output voltage affected by spikes | I41: • OSC - Jitter too high in the output signal | J41: No effect | K41: O | O41: 1 | P41: N | Q41: =F41*O41 -> 0.0046956348 | R41: =IF(P41="N",100%,0%) -> 1 | X41: N
B42: FM_TTL_21 | F42: =F41 -> 0.0046956348 | G42: Incorrect start-up time | I42: No effect | J42: No effect | K42: O | O42: 1 | P42: N | Q42: =F42*O42 -> 0.0046956348 | R42: =IF(P42="N",100%,0%) -> 1 | X42: N
B43: FM_TTL_22 | F43: =F42 -> 0.0046956348 | G43: Output voltage accuracy too low, including drift | I43: • OSC - Out of spec. • Vega - Reset reaction. (POR) | J43: Fail-safe mode active No communication | K43: X | O43: 1 | P43: Y | Q43: =F43*O43 -> 0.0046956348 | R43: 0 | S43: SM11 SM15 SM20 | U43: 0.99 | V43: =IF(P43="N",0,Q43*(1-R43)*(1-U43)) -> 4.6956348e-05 | X43: Y | Y43: =S43 -> SM11 SM15 SM20 | AA43: 1 | AB43: =IF(X43="N",0,(Q43*(1-R43)-V43)*(1-AA43)) -> 0 | AD43: SM15 make the IC enter a safe-sate. Latent coverage: 100%.
...

Sheet PIN ASSIGN
H2: Document ID | J2: =Cover!$F$18 -> ELM-803-FS-0001
H3: Author | J3: =Cover!$F$19 -> Safety Manager | K3: =Cover!$G$19 -> I. Kök
H4: Version | J4: =Cover!$F$20 -> B2
H5: Status | J5: =Cover!$F$21 -> approved after review
A6: FMEDA
A8: =Cover!A9 -> ID803 - Vega
B10: PIN assignment
J11: pin No. | K11: pin Name
J12: 1 | K12: LED4
J13: 2 | K13: LED3
J14: 3 | K14: LED2
J15: 4 | K15: LED1A
J16: 5 | K16: LED1K
J17: 6 | K17: CS
J18: 7 | K18: GND
J19: 8 | K19: FS
J20: 9 | K20: ADC1
J21: 10 | K21: VDDO
J22: 11 | K22: ADC2
J23: 12 | K23: ADDR0
... J59: 48 | K59: LED5K

Sheet PAD(PSP))
V4: Document ID | X4: =Cover!$F$18 -> ELM-803-FS-0001
V5: Author | X5: =Cover!$F$19 -> Safety Manager | Z5: =Cover!$G$19 -> I. Kök
V6: Version | X6: =Cover!$F$20 -> B2
V7: Status | X7: =Cover!$F$21 -> approved after review
A9: FMEDA
A11: =Cover!A9 -> ID803 - Vega
C12: Safety Goal 이 명확한 블록 기반 분석
G14: λ | H14: =SUM(M22:M69) -> 2.4414577
B15: PAD/ESD 보호 소자 영역 고장률(FIT) | E15: ='Core Block FIT rate'!G22/3 -> 2.4414577 | G15: λSPF+λRF | H15: =SUM(R22:R69) -> 0.06663145
B16: Pad count | E16: 48 | G16: λLF | H16: =SUM(X22:X69) -> 0.25238569
K18: Permanent Failures
C19: Golden Master | K19: Single Point Failures | T19: Latent Failure
B20: 고장 모드 번호 PSP (Pad Short to Power) | C20: PIN# | D20: Pad명 | E20: 보호 소자 쇼트처(전원 소스) | F20: 각 PAD 고장율 (FIT) | G20: IC 단품으로써의 영향 | H20: ECU (시스템)에의 영향 | I20: IC단품영향에 대처와 판단 | K20: 비율 (50% 고정) | L20: 안전과 관계되는가? | M20: 항목 고장율(FIT) | N20: 안전 고장의 비율 | O20: 안전 기구 (IC) | P20: 안전 기구 (System) | Q20: 검출율(SPF) | R20: 잔존 고장의 고장율(FIT) | T20: Latent Failure는 안전과 관계되는가? | U20: 안전 기구 (IC) | V20: 안전 기구 (System) | W20: 검출율 | X20: Latent Failure의 고장율(FIT) | Z20: Comment
B21: Failure Mode Number | C21: Pin Number | D21: Pin Name | E21: Power source connected through ESD protection | F21: PAD Failure rate [FIT] | G21: effects on the IC output | H21: effects on the system | I21: memo X - Violation of SG O - No violation | K21: Failure distribution | L21: Single Point Failure mode can violate the safety goal in the absense of safety mecahnism | M21: Failure rate [FIT] | N21: Percentage of Safe Faults | O21: Safety mechanism(s) (IC) allowing to prevent the violation of the safety goal | P21: Safety mechanism(s) (System) allowing to prevent the violation of the safety goal | Q21: Failure mode coverage wrt. violation of safety goal | R21: Residual or Single Point Fault failure rate [FIT] | T21: Latent Failure mode can violate the safety goal in the absense of safety mecahnism | U21: Safety mechanism(s) (IC) to prevent latent faults | V21: Safety mechanism(s) (System) to prevent latent faults | W21: Failure mode coverage wrt. Latent failures | X21: Latent Multiple Point Fault failure rate [FIT]
B22: FM_PSP_1 | C22: 1 | D22: LED4 | F22: =$E$15/$E$16 -> 0.050863702 | G22: Unintended LED turn OFF, high current on pass devices | H22: Unintended LED OFF | I22: X | K22: 1 | L22: Y | M22: =F22*K22 -> 0.050863702 | N22: =IF(L22="N",100%,0%) -> 0 | O22: SM04 SM17 | Q22: 0.99 | R22: =IF(L22="N",0,M22*(1-N22)*(1-Q22)) -> 0.00050863702 | T22: Y | U22: =O22 -> SM04 SM17 | W22: 0.8 | X22: =IF(T22="N",0,(M22*(1-N22)-R22)*(1-W22)) -> 0.010071013
B23: FM_PSP_2 | C23: 2 | D23: LED3 | F23: =$E$15/$E$16 -> 0.050863702 | G23: Unintended LED turn OFF, high current on pass devices | H23: Unintended LED OFF | I23: X | K23: 1 | L23: Y | M23: =F23*K23 -> 0.050863702 | N23: =IF(L23="N",100%,0%) -> 0 | O23: SM04 SM17 | Q23: 0.99 | R23: =IF(L23="N",0,M23*(1-N23)*(1-Q23)) -> 0.00050863702 | T23: Y | U23: =O23 -> SM04 SM17 | W23: 0.8 | X23: =IF(T23="N",0,(M23*(1-N23)-R23)*(1-W23)) -> 0.010071013
B24: FM_PSP_3 | C24: 3 | D24: LED2 | F24: =$E$15/$E$16 -> 0.050863702 | G24: Unintended LED turn OFF, high current on pass devices | H24: Unintended LED OFF | I24: X | K24: 1 | L24: Y | M24: =F24*K24 -> 0.050863702 | N24: =IF(L24="N",100%,0%) -> 0 | O24: SM04 SM17 | Q24: 0.99 | R24: =IF(L24="N",0,M24*(1-N24)*(1-Q24)) -> 0.00050863702 | T24: Y | U24: =O24 -> SM04 SM17 | W24: 0.8 | X24: =IF(T24="N",0,(M24*(1-N24)-R24)*(1-W24)) -> 0.010071013
B25: FM_PSP_4 | C25: 4 | D25: LED1A | F25: =$E$15/$E$16 -> 0.050863702 | G25: Unintended LED turn OFF, high current on pass devices | H25: Unintended LED OFF | I25: X | K25: 1 | L25: Y | M25: =F25*K25 -> 0.050863702 | N25: =IF(L25="N",100%,0%) -> 0 | O25: SM04 SM17 | Q25: 0.99 | R25: =IF(L25="N",0,M25*(1-N25)*(1-Q25)) -> 0.00050863702 | T25: Y | U25: =O25 -> SM04 SM17 | W25: 0.8 | X25: =IF(T25="N",0,(M25*(1-N25)-R25)*(1-W25)) -> 0.010071013
B26: FM_PSP_5 | C26: 5 | D26: LED1K | F26: =$E$15/$E$16 -> 0.050863702 | G26: Current Sense Reading Error | H26: No effect | I26: O | K26: 1 | L26: N | M26: =F26*K26 -> 0.050863702 | N26: =IF(L26="N",100%,0%) -> 1 | T26: =L26 -> N | U26: =O26
B27: FM_PSP_6 | C27: 6 | D27: CS | F27: =$E$15/$E$16 -> 0.050863702 | G27: Current Sense Reading Error | H27: No effect | I27: O | K27: 1 | L27: N | M27: =F27*K27 -> 0.050863702 | N27: =IF(L27="N",100%,0%) -> 1 | T27: N
B28: FM_PSP_7 | C28: 7 | D28: GND | F28: =$E$15/$E$16 -> 0.050863702 | G28: Device power-off | H28: Unintended LED ON | I28: X | K28: 1 | L28: Y | M28: =F28*K28 -> 0.050863702 | N28: =IF(L28="N",100%,0%) -> 0 | O28: SM01 SM15 SM16 SM22 | Q28: 0.99 | R28: =IF(L28="N",0,M28*(1-N28)*(1-Q28)) -> 0.00050863702 | T28: =L28 -> Y | U28: =O28 -> SM01 SM15 SM16 SM22 | W28: 1 | X28: =IF(T28="N",0,(M28*(1-N28)-R28)*(1-W28)) -> 0 | Z28: NOTE 2: SM22 activate safe-state due to VDD fault, 100% MPC.
B29: FM_PSP_8 | C29: 8 | D29: FS | F29: =$E$15/$E$16 -> 0.050863702 | G29: Switches always ON in FS mode | H29: LEDs always OFF in FS mode | I29: O | K29: 1 | L29: N | M29: =F29*K29 -> 0.050863702 | N29: =IF(L29="N",100%,0%) -> 1 | T29: =L29 -> N | U29: =O29
B30: FM_PSP_9 | C30: 9 | D30: ADC1 | F30: =$E$15/$E$16 -> 0.050863702 | G30: Cannot use ADC1 to external reading | H30: No effect | I30: O | K30: 1 | L30: N | M30: =F30*K30 -> 0.050863702 | N30: =IF(L30="N",100%,0%) -> 1 | T30: N
B31: FM_PSP_10 | C31: 10 | D31: VDDO | F31: =$E$15/$E$16 -> 0.050863702 | G31: No effect, same pin | H31: No effect | I31: O | K31: 1 | L31: N | M31: =F31*K31 -> 0.050863702 | N31: =IF(L31="N",100%,0%) -> 1 | T31: N
B32: FM_PSP_11 | C32: 11 | D32: ADC2 | F32: =$E$15/$E$16 -> 0.050863702 | G32: Cannot use ADC1 to external reading | H32: No effect | I32: O | K32: 1 | L32: N | M32: =F32*K32 -> 0.050863702 | N32: =IF(L32="N",100%,0%) -> 1 | T32: N
B33: FM_PSP_12 | C33: 12 | D33: ADDR0 | F33: =$E$15/$E$16 -> 0.050863702 | G33: UART Communication Error. Operate in FS. | H33: Fail-safe mode active | I33: X | K33: 1 | L33: Y | M33: =F33*K33 -> 0.050863702 | N33: =IF(L33="N",100%,0%) -> 0 | O33: SM09 SM10 SM13 | Q33: 0.99 | R33: =IF(L33="N",0,M33*(1-N33)*(1-Q33)) -> 0.00050863702 | T33: =L33 -> Y | U33: =O33 -> SM09 SM10 SM13 | W33: 1 | X33: =IF(T33="N",0,(M33*(1-N33)-R33)*(1-W33)) -> 0 | Z33: NOTE 1
B34: FM_PSP_13 | C34: 13 | D34: VDD | F34: =$E$15/$E$16 -> 0.050863702 | G34: No effect, same pin | H34: No effect | I34: O | K34: 1 | L34: N | M34: =F34*K34 -> 0.050863702 | N34: =IF(L34="N",100%,0%) -> 1 | T34: N
B35: FM_PSP_14 | C35: 14 | D35: SYNC | F35: =$E$15/$E$16 -> 0.050863702 | G35: Unintended LED turn ON/OFF | H35: Unintended LED ON/OFF | I35: X | K35: 1 | L35: Y | M35: =F35*K35 -> 0.050863702 | N35: =IF(L35="N",100%,0%) -> 0 | O35: SM21 | Q35: 0.6 | R35: =IF(L35="N",0,M35*(1-N35)*(1-Q35)) -> 0.020345481 | T35: =L35 -> Y | W35: 0 | X35: =IF(T35="N",0,(M35*(1-N35)-R35)*(1-W35)) -> 0.030518221
B36: FM_PSP_15 | C36: 15 | D36: RX | F36: =$E$15/$E$16 -> 0.050863702 | G36: UART Communication Error. Operate in FS. | H36: Fail-safe mode active | I36: X | K36: 1 | L36: Y | M36: =F36*K36 -> 0.050863702 | N36: =IF(L36="N",100%,0%) -> 0 | O36: SM09 SM10 SM13 | Q36: 0.99 | R36: =IF(L36="N",0,M36*(1-N36)*(1-Q36)) -> 0.00050863702 | T36: =L36 -> Y | U36: =O36 -> SM09 SM10 SM13 | W36: 1 | X36: =IF(T36="N",0,(M36*(1-N36)-R36)*(1-W36)) -> 0 | Z36: NOTE 1
B37: FM_PSP_16 | C37: 16 | D37: NC2 | F37: =$E$15/$E$16 -> 0.050863702 | G37: No effect, no connection pin | H37: No effect | I37: O | K37: 1 | L37: N | M37: =F37*K37 -> 0.050863702 | N37: =IF(L37="N",100%,0%) -> 1 | T37: =L37 -> N | U37: =O37
B38: FM_PSP_17 | C38: 17 | D38: ADDR1 | F38: =$E$15/$E$16 -> 0.050863702 | G38: UART Communication Error. Operate in FS. | H38: Fail-safe mode active | I38: X | K38: 1 | L38: Y | M38: =F38*K38 -> 0.050863702 | N38: =IF(L38="N",100%,0%) -> 0 | O38: SM09 SM10 SM13 | Q38: 0.99 | R38: =IF(L38="N",0,M38*(1-N38)*(1-Q38)) -> 0.00050863702 | T38: =L38 -> Y | U38: =O38 -> SM09 SM10 SM13 | W38: 1 | X38: =IF(T38="N",0,(M38*(1-N38)-R38)*(1-W38)) -> 0 | Z38: NOTE 1: Since SM10 is a self-test for SM9, multi-point coverage is 100%.
B39: FM_PSP_18 | C39: 18 | D39: RX | F39: =$E$15/$E$16 -> 0.050863702 | G39: UART Communication Error. Operate in FS. | H39: Fail-safe mode active | I39: X | K39: 1 | L39: Y | M39: =F39*K39 -> 0.050863702 | N39: =IF(L39="N",100%,0%) -> 0 | O39: SM09 SM10 SM13 | Q39: 0.99 | R39: =IF(L39="N",0,M39*(1-N39)*(1-Q39)) -> 0.00050863702 | T39: =L39 -> Y | U39: =O39 -> SM09 SM10 SM13 | W39: 1 | X39: =IF(T39="N",0,(M39*(1-N39)-R39)*(1-W39)) -> 0
B40: FM_PSP_19 | C40: 19 | D40: CLK_SEL | F40: =$E$15/$E$16 -> 0.050863702 | G40: Cannot communicate at 8MHz. Operate in FS. | H40: Fail-safe mode active | I40: X | K40: 1 | L40: Y | M40: =F40*K40 -> 0.050863702 | N40: =IF(L40="N",100%,0%) -> 0 | O40: SM09 SM10 SM13 | Q40: 0.99 | R40: =IF(L40="N",0,M40*(1-N40)*(1-Q40)) -> 0.00050863702 | T40: =L40 -> Y | U40: =O40 -> SM09 SM10 SM13 | W40: 1 | X40: =IF(T40="N",0,(M40*(1-N40)-R40)*(1-W40)) -> 0
B41: FM_PSP_20 | C41: 20 | D41: TX | F41: =$E$15/$E$16 -> 0.050863702 | G41: UART Communication Error. Operate in FS. | H41: Fail-safe mode active | I41: X | K41: 1 | L41: Y | M41: =F41*K41 -> 0.050863702 | N41: =IF(L41="N",100%,0%) -> 0 | O41: SM09 SM10 SM13 | Q41: 0.99 | R41: =IF(L41="N",0,M41*(1-N41)*(1-Q41)) -> 0.00050863702 | T41: =L41 -> Y | U41: =O41 -> SM09 SM10 SM13 | W41: 1 | X41: =IF(T41="N",0,(M41*(1-N41)-R41)*(1-W41)) -> 0
B42: FM_PSP_21 | C42: 21 | D42: NC1 | F42: =$E$15/$E$16 -> 0.050863702 | G42: No effect, no connection pin | H42: No effect | I42: O | K42: 1 | L42: N | M42: =F42*K42 -> 0.050863702 | N42: =IF(L42="N",100%,0%) -> 1 | T42: =L42 -> N | U42: =O42
B43: FM_PSP_22 | C43: 22 | D43: SYNC | F43: =$E$15/$E$16 -> 0.050863702 | G43: Unintended LED turn ON/OFF | H43: Unintended LED ON/OFF | I43: X | K43: 1 | L43: Y | M43: =F43*K43 -> 0.050863702 | N43: =IF(L43="N",100%,0%) -> 0 | O43: SM21 | Q43: 0.6 | R43: =IF(L43="N",0,M43*(1-N43)*(1-Q43)) -> 0.020345481 | T43: =L43 -> Y | W43: 0 | X43: =IF(T43="N",0,(M43*(1-N43)-R43)*(1-W43)) -> 0.030518221
B44: FM_PSP_23 | C44: 23 | D44: GND2 | F44: =$E$15/$E$16 -> 0.050863702 | G44: Device power-off | H44: Unintended LED ON | I44: X | K44: 1 | L44: Y | M44: =F44*K44 -> 0.050863702 | N44: =IF(L44="N",100%,0%) -> 0 | O44: SM01 SM15 SM16 SM22 | Q44: 0.99 | R44: =IF(L44="N",0,M44*(1-N44)*(1-Q44)) -> 0.00050863702 | T44: =L44 -> Y | U44: =O44 -> SM01 SM15 SM16 SM22 | W44: 1 | X44: =IF(T44="N",0,(M44*(1-N44)-R44)*(1-W44)) -> 0 | Z44: NOTE 2
B45: FM_PSP_24 | C45: 24 | D45: TX | F45: =$E$15/$E$16 -> 0.050863702 | G45: UART Communication Error. Operate in FS. | H45: Fail-safe mode active | I45: X | K45: 1 | L45: Y | M45: =F45*K45 -> 0.050863702 | N45: =IF(L45="N",100%,0%) -> 0 | O45: SM09 SM10 SM13 | Q45: 0.99 | R45: =IF(L45="N",0,M45*(1-N45)*(1-Q45)) -> 0.00050863702 | T45: =L45 -> Y | U45: =O45 -> SM09 SM10 SM13 | W45: 1 | X45: =IF(T45="N",0,(M45*(1-N45)-R45)*(1-W45)) -> 0 | Z45: NOTE 1
B46: FM_PSP_25 | C46: 25 | D46: LED5K | F46: =$E$15/$E$16 -> 0.050863702 | G46: Unintended LED turn OFF, high current on pass devices | H46: Unintended LED OFF | I46: X | K46: 1 | L46: Y | M46: =F46*K46 -> 0.050863702 | N46: =IF(L46="N",100%,0%) -> 0 | O46: SM04 SM17 | Q46: 0.99 | R46: =IF(L46="N",0,M46*(1-N46)*(1-Q46)) -> 0.00050863702 | T46: Y | U46: =O46 -> SM04 SM17 | W46: 0.8 | X46: =IF(T46="N",0,(M46*(1-N46)-R46)*(1-W46)) -> 0.010071013
B47: FM_PSP_26 | C47: 26 | D47: LED11 | F47: =$E$15/$E$16 -> 0.050863702 | G47: Unintended LED turn OFF, high current on pass devices | H47: Unintended LED OFF | I47: X | K47: 1 | L47: Y | M47: =F47*K47 -> 0.050863702 | N47: =IF(L47="N",100%,0%) -> 0 | O47: SM04 SM17 | Q47: 0.99 | R47: =IF(L47="N",0,M47*(1-N47)*(1-Q47)) -> 0.00050863702 | T47: Y | U47: =O47 -> SM04 SM17 | W47: 0.8 | X47: =IF(T47="N",0,(M47*(1-N47)-R47)*(1-W47)) -> 0.010071013
...

Sheet PAD(PSG))
V4: Document ID | X4: =Cover!$F$18 -> ELM-803-FS-0001
V5: Author | X5: =Cover!$F$19 -> Safety Manager | Z5: =Cover!$G$19 -> I. Kök
V6: Version | X6: =Cover!$F$20 -> B2
V7: Status | X7: =Cover!$F$21 -> approved after review
A9: FMEDA
A11: =Cover!A9 -> ID803 - Vega
C12: Safety Goal 이 명확한 블록 기반 분석
G14: λ | H14: =SUM(M22:M69) -> 2.4414577
B15: PAD/ESD 보호 소자 영역 고장률(FIT) | E15: ='Core Block FIT rate'!G22/3 -> 2.4414577 | G15: λSPF+λRF | H15: =SUM(R22:R69) -> 0.066122813
B16: Pad count | E16: ='PAD(PSP))'!E16 -> 48 | G16: λLF | H16: =SUM(X22:X69) -> 0.25238569
K18: Permanent Failures
C19: Golden Master | K19: Single Point Failures | T19: Latent Failure
B20: 고장 모드 번호 PSG (Pad Short to GND) | C20: PIN# | D20: Pad명 | E20: 보호 소자 쇼트처(전원 소스) | F20: 각 PAD 고장율 (FIT) | G20: IC 단품으로써의 영향 | H20: ECU (시스템)에의 영향 | I20: IC단품영향에 대처와 판단 | K20: 비율 (50% 고정) | L20: 안전과 관계되는가? | M20: 항목 고장율(FIT) | N20: 안전 고장의 비율 | O20: 안전 기구 (IC) | P20: 안전 기구 (System) | Q20: 검출율(SPF) | R20: 잔존 고장의 고장율(FIT) | T20: Latent Failure는 안전과 관계되는가? | U20: 안전 기구 (IC) | V20: 안전 기구 (System) | W20: 검출율 | X20: Latent Failure의 고장율(FIT) | Z20: Comment
B21: Failure Mode Number | C21: Pin Number | D21: Pin Name | E21: Power source connected through ESD protection | F21: PAD Failure rate [FIT] | G21: effects on the IC output | H21: effects on the system | I21: memo X - Violation of SG O - No violation | K21: Failure distribution | L21: Single Point Failure mode can violate the safety goal in the absense of safety mecahnism | M21: Failure rate [FIT] | N21: Percentage of Safe Faults | O21: Safety mechanism(s) (IC) allowing to prevent the violation of the safety goal | P21: Safety mechanism(s) (System) allowing to prevent the violation of the safety goal | Q21: Failure mode coverage wrt. violation of safety goal | R21: Residual or Single Point Fault failure rate [FIT] | T21: Latent Failure mode can violate the safety goal in the absense of safety mecahnism | U21: Safety mechanism(s) (IC) to prevent latent faults | V21: Safety mechanism(s) (System) to prevent latent faults | W21: Failure mode coverage wrt. Latent failures | X21: Latent Multiple Point Fault failure rate [FIT]
B22: FM_PSG_1 | C22: 1 | D22: LED4 | F22: =$E$15/$E$16 -> 0.050863702 | G22: Unintended LED turn OFF | H22: Unintended LED OFF | I22: X | K22: 1 | L22: Y | M22: =F22*K22 -> 0.050863702 | N22: =IF(L22="N",100%,0%) -> 0 | O22: SM05 SM06 | Q22: 0.99 | R22: =IF(L22="N",0,M22*(1-N22)*(1-Q22)) -> 0.00050863702 | T22: =L22 -> Y | U22: =O22 -> SM05 SM06 | W22: 0.8 | X22: =IF(T22="N",0,(M22*(1-N22)-R22)*(1-W22)) -> 0.010071013 | Z22: NOTE 2: SM06 Driver health check can be used to MPF.
B23: FM_PSG_2 | C23: 2 | D23: LED3 | F23: =$E$15/$E$16 -> 0.050863702 | G23: Unintended LED turn OFF | H23: Unintended LED OFF | I23: X | K23: 1 | L23: Y | M23: =F23*K23 -> 0.050863702 | N23: =IF(L23="N",100%,0%) -> 0 | O23: SM05 SM06 | Q23: 0.99 | R23: =IF(L23="N",0,M23*(1-N23)*(1-Q23)) -> 0.00050863702 | T23: =L23 -> Y | U23: =O23 -> SM05 SM06 | W23: 0.8 | X23: =IF(T23="N",0,(M23*(1-N23)-R23)*(1-W23)) -> 0.010071013 | Z23: NOTE 2
B24: FM_PSG_3 | C24: 3 | D24: LED2 | F24: =$E$15/$E$16 -> 0.050863702 | G24: Unintended LED turn OFF | H24: Unintended LED OFF | I24: X | K24: 1 | L24: Y | M24: =F24*K24 -> 0.050863702 | N24: =IF(L24="N",100%,0%) -> 0 | O24: SM05 SM06 | Q24: 0.99 | R24: =IF(L24="N",0,M24*(1-N24)*(1-Q24)) -> 0.00050863702 | T24: =L24 -> Y | U24: =O24 -> SM05 SM06 | W24: 0.8 | X24: =IF(T24="N",0,(M24*(1-N24)-R24)*(1-W24)) -> 0.010071013 | Z24: NOTE 2
B25: FM_PSG_4 | C25: 4 | D25: LED1A | F25: =$E$15/$E$16 -> 0.050863702 | G25: Unintended LED turn OFF | H25: Unintended LED OFF | I25: X | K25: 1 | L25: Y | M25: =F25*K25 -> 0.050863702 | N25: =IF(L25="N",100%,0%) -> 0 | O25: SM05 SM06 | Q25: 0.99 | R25: =IF(L25="N",0,M25*(1-N25)*(1-Q25)) -> 0.00050863702 | T25: =L25 -> Y | U25: =O25 -> SM05 SM06 | W25: 0.8 | X25: =IF(T25="N",0,(M25*(1-N25)-R25)*(1-W25)) -> 0.010071013 | Z25: NOTE 2
B26: FM_PSG_5 | C26: 5 | D26: LED1K | F26: =$E$15/$E$16 -> 0.050863702 | G26: Current Sense Reading Error | H26: No effect | I26: O | K26: 1 | L26: N | M26: =F26*K26 -> 0.050863702 | N26: =IF(L26="N",100%,0%) -> 1 | T26: =L26 -> N | U26: =O26
B27: FM_PSG_6 | C27: 6 | D27: CS | F27: =$E$15/$E$16 -> 0.050863702 | G27: Current Sense Reading Error | H27: No effect | I27: O | K27: 1 | L27: N | M27: =F27*K27 -> 0.050863702 | N27: =IF(L27="N",100%,0%) -> 1 | T27: =L27 -> N | U27: =O27
B28: FM_PSG_7 | C28: 7 | D28: GND | F28: =$E$15/$E$16 -> 0.050863702 | G28: No effect, same pin | H28: No effect | I28: O | K28: 1 | L28: N | M28: =F28*K28 -> 0.050863702 | N28: =IF(L28="N",100%,0%) -> 1 | T28: =L28 -> N | U28: =O28
B29: FM_PSG_8 | C29: 8 | D29: FS | F29: =$E$15/$E$16 -> 0.050863702 | G29: Switches always OFF in FS mode | H29: LEDs always OFF in FS mode | I29: O | K29: 1 | L29: N | M29: =F29*K29 -> 0.050863702 | N29: =IF(L29="N",100%,0%) -> 1 | T29: =L29 -> N | U29: =O29
B30: FM_PSG_9 | C30: 9 | D30: ADC1 | F30: =$E$15/$E$16 -> 0.050863702 | G30: Cannot use ADC1 to external reading | H30: No effect | I30: O | K30: 1 | L30: N | M30: =F30*K30 -> 0.050863702 | N30: =IF(L30="N",100%,0%) -> 1 | T30: =L30 -> N | U30: =O30
B31: FM_PSG_10 | C31: 10 | D31: VDDO | F31: =$E$15/$E$16 -> 0.050863702 | G31: Device power-off | H31: Unintended LED ON | I31: X | K31: 1 | L31: Y | M31: =F31*K31 -> 0.050863702 | N31: =IF(L31="N",100%,0%) -> 0 | O31: SM01 SM15 SM16 SM22 | Q31: 0.99 | R31: =IF(L31="N",0,M31*(1-N31)*(1-Q31)) -> 0.00050863702 | T31: =L31 -> Y | U31: =O31 -> SM01 SM15 SM16 SM22 | W31: 1 | X31: =IF(T31="N",0,(M31*(1-N31)-R31)*(1-W31)) -> 0 | Z31: NOTE 4: SM22 activate safe-state due to VDD fault, 100% MPC.
B32: FM_PSG_11 | C32: 11 | D32: ADC2 | F32: =$E$15/$E$16 -> 0.050863702 | G32: Cannot use ADC1 to external reading | H32: No effect | I32: O | K32: 1 | L32: N | M32: =F32*K32 -> 0.050863702 | N32: =IF(L32="N",100%,0%) -> 1 | T32: =L32 -> N | U32: =O32
B33: FM_PSG_12 | C33: 12 | D33: ADDR0 | F33: =$E$15/$E$16 -> 0.050863702 | G33: UART Communication Error. Operate in FS. | H33: Fail-safe mode active | I33: X | K33: 1 | L33: Y | M33: =F33*K33 -> 0.050863702 | N33: =IF(L33="N",100%,0%) -> 0 | O33: SM09 SM10 SM13 | Q33: 0.99 | R33: =IF(L33="N",0,M33*(1-N33)*(1-Q33)) -> 0.00050863702 | T33: =L33 -> Y | U33: =O33 -> SM09 SM10 SM13 | W33: 1 | X33: =IF(T33="N",0,(M33*(1-N33)-R33)*(1-W33)) -> 0 | Z33: NOTE 1
B34: FM_PSG_13 | C34: 13 | D34: VDD | F34: =$E$15/$E$16 -> 0.050863702 | G34: Device power-off | H34: Unintended LED ON | I34: X | K34: 1 | L34: Y | M34: =F34*K34 -> 0.050863702 | N34: =IF(L34="N",100%,0%) -> 0 | O34: SM01 SM15 SM16 SM22 | Q34: 0.99 | R34: =IF(L34="N",0,M34*(1-N34)*(1-Q34)) -> 0.00050863702 | T34: =L34 -> Y | U34: =O34 -> SM01 SM15 SM16 SM22 | W34: 1 | X34: =IF(T34="N",0,(M34*(1-N34)-R34)*(1-W34)) -> 0 | Z34: NOTE 4
B35: FM_PSG_14 | C35: 14 | D35: SYNC | F35: =$E$15/$E$16 -> 0.050863702 | G35: Unintended LED turn ON/OFF | H35: Unintended LED turn ON/OFF | I35: X | K35: 1 | L35: Y | M35: =F35*K35 -> 0.050863702 | N35: =IF(L35="N",100%,0%) -> 0 | O35: SM21 | Q35: 0.6 | R35: =IF(L35="N",0,M35*(1-N35)*(1-Q35)) -> 0.020345481 | T35: =L35 -> Y | W35: 0 | X35: =IF(T35="N",0,(M35*(1-N35)-R35)*(1-W35)) -> 0.030518221
B36: FM_PSG_15 | C36: 15 | D36: RX | F36: =$E$15/$E$16 -> 0.050863702 | G36: UART Communication Error. Operate in FS. | H36: Fail-safe mode active | I36: X | K36: 1 | L36: Y | M36: =F36*K36 -> 0.050863702 | N36: =IF(L36="N",100%,0%) -> 0 | O36: SM09 SM10 SM13 | Q36: 0.99 | R36: =IF(L36="N",0,M36*(1-N36)*(1-Q36)) -> 0.00050863702 | T36: =L36 -> Y | U36: =O36 -> SM09 SM10 SM13 | W36: 1 | X36: =IF(T36="N",0,(M36*(1-N36)-R36)*(1-W36)) -> 0 | Z36: NOTE 1
B37: FM_PSG_16 | C37: 16 | D37: NC2 | F37: =$E$15/$E$16 -> 0.050863702 | G37: No effect, no connection pin | H37: No effect | I37: O | K37: 1 | L37: N | M37: =F37*K37 -> 0.050863702 | N37: =IF(L37="N",100%,0%) -> 1 | T37: =L37 -> N | U37: =O37
B38: FM_PSG_17 | C38: 17 | D38: ADDR1 | F38: =$E$15/$E$16 -> 0.050863702 | G38: UART Communication Error. Operate in FS. | H38: Fail-safe mode active | I38: X | K38: 1 | L38: Y | M38: =F38*K38 -> 0.050863702 | N38: =IF(L38="N",100%,0%) -> 0 | O38: SM09 SM10 SM13 | Q38: 0.99 | R38: =IF(L38="N",0,M38*(1-N38)*(1-Q38)) -> 0.00050863702 | T38: =L38 -> Y | U38: =O38 -> SM09 SM10 SM13 | W38: 1 | X38: =IF(T38="N",0,(M38*(1-N38)-R38)*(1-W38)) -> 0 | Z38: NOTE 1: Since SM10 is a self-test for SM9, multi-point coverage is 100%.
B39: FM_PSG_18 | C39: 18 | D39: RX | F39: =$E$15/$E$16 -> 0.050863702 | G39: UART Communication Error. Operate in FS. | H39: Fail-safe mode active | I39: X | K39: 1 | L39: Y | M39: =F39*K39 -> 0.050863702 | N39: =IF(L39="N",100%,0%) -> 0 | O39: SM09 SM10 SM13 | Q39: 0.99 | R39: =IF(L39="N",0,M39*(1-N39)*(1-Q39)) -> 0.00050863702 | T39: =L39 -> Y | U39: =O39 -> SM09 SM10 SM13 | W39: 1 | X39: =IF(T39="N",0,(M39*(1-N39)-R39)*(1-W39)) -> 0
B40: FM_PSG_19 | C40: 19 | D40: CLK_SEL | F40: =$E$15/$E$16 -> 0.050863702 | G40: Cannot communicate at 16MHz. Operate in FS. | H40: Fail-safe mode active | I40: X | K40: 1 | L40: Y | M40: =F40*K40 -> 0.050863702 | N40: =IF(L40="N",100%,0%) -> 0 | O40: SM09 SM10 SM13 | Q40: 0.99 | R40: =IF(L40="N",0,M40*(1-N40)*(1-Q40)) -> 0.00050863702 | T40: =L40 -> Y | U40: =O40 -> SM09 SM10 SM13 | W40: 1 | X40: =IF(T40="N",0,(M40*(1-N40)-R40)*(1-W40)) -> 0
B41: FM_PSG_20 | C41: 20 | D41: TX | F41: =$E$15/$E$16 -> 0.050863702 | G41: UART Communication Error. Operate in FS. | H41: Fail-safe mode active | I41: X | K41: 1 | L41: Y | M41: =F41*K41 -> 0.050863702 | N41: =IF(L41="N",100%,0%) -> 0 | O41: SM09 SM10 SM13 | Q41: 0.99 | R41: =IF(L41="N",0,M41*(1-N41)*(1-Q41)) -> 0.00050863702 | T41: =L41 -> Y | U41: =O41 -> SM09 SM10 SM13 | W41: 1 | X41: =IF(T41="N",0,(M41*(1-N41)-R41)*(1-W41)) -> 0
B42: FM_PSG_21 | C42: 21 | D42: NC1 | F42: =$E$15/$E$16 -> 0.050863702 | G42: No effect, no connection pin | H42: No effect | I42: O | K42: 1 | L42: N | M42: =F42*K42 -> 0.050863702 | N42: =IF(L42="N",100%,0%) -> 1 | T42: =L42 -> N | U42: =O42
B43: FM_PSG_22 | C43: 22 | D43: SYNC | F43: =$E$15/$E$16 -> 0.050863702 | G43: Unintended LED turn ON/OFF | H43: Unintended LED turn ON/OFF | I43: X | K43: 1 | L43: Y | M43: =F43*K43 -> 0.050863702 | N43: =IF(L43="N",100%,0%) -> 0 | O43: SM21 | Q43: 0.6 | R43: =IF(L43="N",0,M43*(1-N43)*(1-Q43)) -> 0.020345481 | T43: =L43 -> Y | W43: 0 | X43: =IF(T43="N",0,(M43*(1-N43)-R43)*(1-W43)) -> 0.030518221
B44: FM_PSG_23 | C44: 23 | D44: GND2 | F44: =$E$15/$E$16 -> 0.050863702 | G44: No effect, same pin | H44: No effect | I44: O | K44: 1 | L44: N | M44: =F44*K44 -> 0.050863702 | N44: =IF(L44="N",100%,0%) -> 1 | T44: =L44 -> N | U44: =O44
B45: FM_PSG_24 | C45: 24 | D45: TX | F45: =$E$15/$E$16 -> 0.050863702 | G45: UART Communication Error. Operate in FS. | H45: Fail-safe mode active | I45: X | K45: 1 | L45: Y | M45: =F45*K45 -> 0.050863702 | N45: =IF(L45="N",100%,0%) -> 0 | O45: SM09 SM10 SM13 | Q45: 0.99 | R45: =IF(L45="N",0,M45*(1-N45)*(1-Q45)) -> 0.00050863702 | T45: =L45 -> Y | U45: =O45 -> SM09 SM10 SM13 | W45: 1 | X45: =IF(T45="N",0,(M45*(1-N45)-R45)*(1-W45)) -> 0 | Z45: NOTE 1
B46: FM_PSG_25 | C46: 25 | D46: LED5K | F46: =$E$15/$E$16 -> 0.050863702 | G46: Unintended LED turn OFF | H46: Unintended LED OFF | I46: X | K46: 1 | L46: Y | M46: =F46*K46 -> 0.050863702 | N46: =IF(L46="N",100%,0%) -> 0 | O46: SM05 SM06 | Q46: 0.99 | R46: =IF(L46="N",0,M46*(1-N46)*(1-Q46)) -> 0.00050863702 | T46: =L46 -> Y | U46: =O46 -> SM05 SM06 | W46: 0.8 | X46: =IF(T46="N",0,(M46*(1-N46)-R46)*(1-W46)) -> 0.010071013 | Z46: NOTE 2
B47: FM_PSG_26 | C47: 26 | D47: LED11 | F47: =$E$15/$E$16 -> 0.050863702 | G47: Unintended LED turn OFF | H47: Unintended LED OFF | I47: X | K47: 1 | L47: Y | M47: =F47*K47 -> 0.050863702 | N47: =IF(L47="N",100%,0%) -> 0 | O47: SM05 SM06 | Q47: 0.99 | R47: =IF(L47="N",0,M47*(1-N47)*(1-Q47)) -> 0.00050863702 | T47: =L47 -> Y | U47: =O47 -> SM05 SM06 | W47: 0.8 | X47: =IF(T47="N",0,(M47*(1-N47)-R47)*(1-W47)) -> 0.010071013 | Z47: NOTE 2
...

Sheet Bonding(OPEN) 
V4: Document ID | X4: =Cover!$F$18 -> ELM-803-FS-0001
V5: Author | X5: =Cover!$F$19 -> Safety Manager | AA5: =Cover!$G$19 -> I. Kök
V6: Version | X6: =Cover!$F$20 -> B2
V7: Status | X7: =Cover!$F$21 -> approved after review
A9: FMEDA
A11: =Cover!A9 -> ID803 - Vega
C12: Safety Goal 이 명확한 블록 기반 분석
H15: λ | I15: =SUM(N23:N70) -> 65.919358
C16: Package Failure rate [FIT] | F16: ='Core Block FIT rate'!G23 -> 65.919358 | H16: λSPF+λRF | I16: =SUM(S23:S70) -> 1.7990492
C17: Bonding | F17: 48 | H17: λLF | I17: =SUM(Y23:Y70) -> 7.086331
L19: Permanent Failures
C20: Golden Master | L20: Single Point Failures | U20: Latent Failures
